<robot name="autolabor_description" xmlns:xacro="http://ros.org/wiki/xacro">>
  <xacro:include filename="$(find velodyne_description)/urdf/VLP-16.urdf.xacro"/>
  <xacro:include filename="$(find pja)/urdf/common_properties.xacro"/>
  <xacro:include filename="$(find pja)/urdf/turtlebot3_burger.gazebo.xacro"/>

  <link name="base_footprint"/>

  <joint name="base_joint" type="fixed">
    <parent link="base_footprint"/>
    <child link="base_link"/>
    <origin xyz="0.0 0.0 0.010" rpy="0 0 0"/>
  </joint>

<!--  <link name="base_link"/>-->


  <link name="base_link">
    <visual>
      <origin
              xyz="-0.363 0.3085 0.2883"
              rpy="0. 1.57 -1.57"/>
      <geometry>
        <mesh
                filename="package://autolabor_description/meshes/autolabor_pro1.stl" scale="0.001 0.001 0.001"/>
      </geometry>
      <material
              name="">
        <color
                rgba="0.96 0.81 0.36 1"/>
      </material>
      <collision>
        <origin xyz="-0.032 0 0.070" rpy="0 0 0"/>
        <geometry>
          <box size="0.140 0.140 0.143"/>
        </geometry>
      </collision>

      <inertial>
        <origin xyz="0 0 0" rpy="0 0 0"/>
        <mass value="8.2573504e-02"/>
        <inertia ixx="2.2124416e-03" ixy="-1.2294101e-05" ixz="3.4938785e-05"
                 iyy="2.1193702e-03" iyz="-5.0120904e-06"
                 izz="2.0064271e-03" />
      </inertial>
    </visual>
  </link>

  <joint name="lidar_holder_joint" type="fixed">
    <origin xyz="0.0 0 0.7" rpy="0 0 0"/>
    <parent link="base_link"/>
    <child link="lidar_holder"/>
  </joint>

  <link name="lidar_holder">
    <visual>
      <origin xyz="0 0 0" rpy="0 0 0"/>
      <geometry>
        <cylinder radius="0.03" length="0.5"/>
      </geometry>
    </visual>

    <inertial>
      <mass value="1e-5" />
      <origin xyz="0 0 0" rpy="0 0 0"/>
      <inertia ixx="1e-6" ixy="0" ixz="0" iyy="1e-6" iyz="0" izz="1e-6" />
    </inertial>
  </link>

  <xacro:VLP-16 parent="lidar_holder" name="velodyne" topic="/velodyne_points" hz="10" samples="350" min_range="0" max_range="5" organize_cloud="true">
    <origin xyz="0 0 0.17" rpy="0 0 0" />
  </xacro:VLP-16>


  <joint name="wheel_left_joint" type="continuous">
    <parent link="base_link"/>
    <child link="wheel_left_link"/>
    <origin xyz="0.1 0.1 0.023" rpy="-1.57 0 0"/>
    <axis xyz="0 0 1"/>
  </joint>

  <link name="wheel_left_link">
    <visual>
      <origin xyz="0 0 0" rpy="1.57 0 0"/>
      <geometry>
        <mesh filename="package://turtlebot3_description/meshes/wheels/left_tire.stl" scale="0.001 0.001 0.001"/>
      </geometry>
      <material name="dark"/>
    </visual>

    <collision>
      <origin xyz="0 0 0" rpy="0 0 0"/>
      <geometry>
        <cylinder length="0.018" radius="0.033"/>
      </geometry>
    </collision>

    <inertial>
      <origin xyz="0 0 0" />
      <mass value="2.8498940e-02" />
      <inertia ixx="1.1175580e-05" ixy="-4.2369783e-11" ixz="-5.9381719e-09"
               iyy="1.1192413e-05" iyz="-1.4400107e-11"
               izz="2.0712558e-05" />
    </inertial>
  </link>

  <joint name="wheel_right_joint" type="continuous">
    <parent link="base_link"/>
    <child link="wheel_right_link"/>
    <origin xyz="0.1 -0.10 0.023" rpy="-1.57 0 0"/>
    <axis xyz="0 0 1"/>
  </joint>

  <joint name="imu_joint" type="fixed">
    <parent link="base_link"/>
    <child link="imu_link"/>
    <origin xyz="0 0 0.068" rpy="0 0 0"/>
  </joint>

  <joint name="caster_back_joint" type="fixed">
    <parent link="base_link"/>
    <child link="caster_back_link"/>
    <origin xyz="-0.081 0 -0.004" rpy="-1.57 0 0"/>
  </joint>

  <link name="caster_back_link">
    <collision>
      <origin xyz="0 0.001 0" rpy="0 0 0"/>
      <geometry>
        <box size="0.030 0.009 0.020"/>
      </geometry>
    </collision>

    <inertial>
      <origin xyz="0 0 0" />
      <mass value="0.005" />
      <inertia ixx="0.001" ixy="0.0" ixz="0.0"
               iyy="0.001" iyz="0.0"
               izz="0.001" />
    </inertial>
  </link>


  <link name="imu_link"/>

  <link name="wheel_right_link">
    <visual>
      <origin xyz="0 0 0" rpy="1.57 0 0"/>
      <geometry>
        <mesh filename="package://turtlebot3_description/meshes/wheels/right_tire.stl" scale="0.001 0.001 0.001"/>
      </geometry>
      <material name="dark"/>
    </visual>

    <collision>
      <origin xyz="0 0 0" rpy="0 0 0"/>
      <geometry>
        <cylinder length="0.018" radius="0.033"/>
      </geometry>
    </collision>

    <inertial>
      <origin xyz="0 0 0" />
      <mass value="2.8498940e-02" />
      <inertia ixx="1.1175580e-05" ixy="-4.2369783e-11" ixz="-5.9381719e-09"
               iyy="1.1192413e-05" iyz="-1.4400107e-11"
               izz="2.0712558e-05" />
    </inertial>
  </link>

<!--  <link name="laser">-->
<!--    <visual>-->
<!--      <origin xyz="0 0 0"/>-->
<!--      <geometry>-->
<!--        <cylinder length="0.05" radius="0.03"/>-->
<!--      </geometry>-->
<!--      <material name="gray"/>-->
<!--    </visual>-->
<!--  </link>-->

<!--  <joint name="laser_link_joint" type="fixed">-->
<!--    <parent link="base_link"/>-->
<!--    <child link="laser"/>-->
<!--    <origin xyz="0.0 0.0 0.5" rpy="0.0 0.0 1.57"/>-->
<!--  </joint>-->

</robot>
